Workbook
Name Code: List!$A$1:$A$14

Sheet Expense Report
C2: Avant Ministries
C3: Expense Report 2026
C7: Name | G7: Date submitted
C10: Account/Project number (one per report) | G10: Field
D13: Total expenses | H13: =H154 -> 0
D15: Advanced funds received | H15: =-H37 -> 0
D17: Funds received directly | H17: =-H165 -> 0
D19: Balance due to worker | H19: =H13+H15+H17 -> 0
D21: (Taxable Total | H21: =SUMIF(J42:J56,"x",H42:H56)+SUMIF(J61:J75,"x",H61:H75)+SUMIF(J80:J104,"x",H80:H104)+SUMIF(J111:J151,"x",H111:H151) -> 0 | I21: )
C25: Worker signature | G25: Date
C28: Supervisor approval | G28: Title
C31: Accounting approval
A34: Advanced Funds Received
H35: Amount
B36: Date Received | D36: Amount and Explanation of Advance | H36: to be Cleared
A39: Travel - air, bus, taxi (attach receipts for amounts over $75, please mark dependent travel as taxable) | M39: Optional
F40: Cost in USD or | G40: Exchange Rate | H40: Cost in | J40: Taxable | K40: Advanced | M40: Accounting Code
B41: Date | C41: From | D41: To | E41: Ministry Purpose | F41: Local Currency | G41: Local To USD | H41: USD | J41: "x" | K41: "x" | M41: (Select from Dropdown)
A42: 1 | H42: =IF(F42>0,IF(G42>0, (F42*G42),IF(#REF!>0,F42/#REF!,F42)),"")
A43: 2
A44: 3 | H44: =IF(F44>0,IF(G44>0, (F44*G44),IF(#REF!>0,F44/#REF!,F44)),"")
A45: 4 | H45: =IF(F45>0,IF(G45>0, (F45*G45),IF(#REF!>0,F45/#REF!,F45)),"")
A46: 5 | H46: =IF(F46>0,IF(G46>0, (F46*G46),IF(#REF!>0,F46/#REF!,F46)),"")
A47: 6 | H47: =IF(F47>0,IF(G47>0, (F47*G47),IF(#REF!>0,F47/#REF!,F47)),"")
A48: 7 | H48: =IF(F48>0,IF(G48>0, (F48*G48),IF(#REF!>0,F48/#REF!,F48)),"")
A49: 8 | H49: =IF(F49>0,IF(G49>0, (F49*G49),IF(#REF!>0,F49/#REF!,F49)),"")
A50: 9 | H50: =IF(F50>0,IF(G50>0, (F50*G50),IF(#REF!>0,F50/#REF!,F50)),"")
A51: 10 | H51: =IF(F51>0,IF(G51>0, (F51*G51),IF(#REF!>0,F51/#REF!,F51)),"")
A52: 11 | H52: =IF(F52>0,IF(G52>0, (F52*G52),IF(#REF!>0,F52/#REF!,F52)),"")
A53: 12 | H53: =IF(F53>0,IF(G53>0, (F53*G53),IF(#REF!>0,F53/#REF!,F53)),"")
A54: 13 | H54: =IF(F54>0,IF(G54>0, (F54*G54),IF(#REF!>0,F54/#REF!,F54)),"")
A55: 14 | H55: =IF(F55>0,IF(G55>0, (F55*G55),IF(#REF!>0,F55/#REF!,F55)),"")
A56: 15 | H56: =IF(F56>0,IF(G56>0, (F56*G56),IF(#REF!>0,F56/#REF!,F56)),"")
A58: Ministry Entertainment (attach receipts for amounts over $75, please mark dependent entertainment as taxable): | M58: Optional
F59: Cost in USD or | G59: Exchange Rate | H59: Cost in | J59: Taxable | K59: Advanced | M59: Accounting
B60: Date | C60: Who | D60: Where | E60: Ministry Purpose | F60: Local Currency | G60: Local To USD | H60: USD | J60: "x" | K60: "x" | M60: Code
A61: 16 | H61: =IF(F61>0,IF(G61>0, (F61*G61),IF(#REF!>0,F61/#REF!,F61)),"")
A62: 17 | H62: =IF(F62>0,IF(G62>0, (F62*G62),IF(#REF!>0,F62/#REF!,F62)),"")
A63: 18 | H63: =IF(F63>0,IF(G63>0, (F63*G63),IF(#REF!>0,F63/#REF!,F63)),"")
A64: 19 | H64: =IF(F64>0,IF(G64>0, (F64*G64),IF(#REF!>0,F64/#REF!,F64)),"")
...

Sheet Totals
A1: =IF('Expense Report'!C9=0,"No number entered",'Expense Report'!C9) -> No number entered | B1: =IF('Expense Report'!C6=0,"No name entered",'Expense Report'!C6) -> No name entered
B3: Amount
A4: 8401 - Salary | B4: =SUMIF('Expense Report'!$M$37:$M$129,A4,'Expense Report'!$H$37:$H$129) -> 0
A5: 8407 - Utilities | B5: =SUMIF('Expense Report'!$M$37:$M$129,A5,'Expense Report'!$H$37:$H$129) -> 0
A6: 8420 - Travel | B6: =SUMIF('Expense Report'!$M$37:$M$129,A6,'Expense Report'!$H$37:$H$129) -> 0
A7: 8433 - Printing | B7: =SUMIF('Expense Report'!$M$37:$M$129,A7,'Expense Report'!$H$37:$H$129) -> 0
A8: 8434 - Office Supplies | B8: =SUMIF('Expense Report'!$M$37:$M$129,A8,'Expense Report'!$H$37:$H$129) -> 0
A9: 8435 - Food | B9: =SUMIF('Expense Report'!$M$37:$M$129,A9,'Expense Report'!$H$37:$H$129) -> 0
A10: 8440 - Office Equipment | B10: =SUMIF('Expense Report'!$M$37:$M$129,A10,'Expense Report'!$H$37:$H$129) -> 0
A11: 8441 - Computers & Technology | B11: =SUMIF('Expense Report'!$M$37:$M$129,A11,'Expense Report'!$H$37:$H$129) -> 0
A12: 8451 - Construction | B12: =SUMIF('Expense Report'!$M$37:$M$129,A12,'Expense Report'!$H$37:$H$129) -> 0
A13: 8457 - Postage | B13: =SUMIF('Expense Report'!$M$37:$M$129,A13,'Expense Report'!$H$37:$H$129) -> 0
A14: 8459 - Legal & Audit | B14: =SUMIF('Expense Report'!$M$37:$M$129,A14,'Expense Report'!$H$37:$H$129) -> 0
A15: 8464 - Meals & Entertainment | B15: =SUMIF('Expense Report'!$M$37:$M$129,A15,'Expense Report'!$H$37:$H$129) -> 0
... A17: 8473 - Training | B17: =SUMIF('Expense Report'!$M$37:$M$129,A17,'Expense Report'!$H$37:$H$129) -> 0
A19: 5100.001 - Contributions | B19: =-'Expense Report'!H165 -> 0
A21: 2199.150 - Taxable | B21: =-'Expense Report'!H21 -> 0
A22: 2010.150 - Taxable | B22: ='Expense Report'!H21 -> 0
A24: 2010.114 - Advance | B24: =-'Expense Report'!H37 -> 0
A26: Total | B26: =SUM(B4:B24) -> 0

Sheet List
A1: 8401 - Salary
A2: 8407 - Utilities
A3: 8420 - Travel
A4: 8433 - Printing
A5: 8434 - Office Supplies
A6: 8435 - Food
A7: 8440 - Office Equipment
A8: 8441 - Computers & Technology
A9: 8451 - Construction
A10: 8457 - Postage
A11: 8459 - Legal & Audit
A12: 8464 - Meals & Entertainment
... A14: 8473 - Training
